<?xml version="1.0" ?>
<!-- =================================================================================== -->
<!-- |    This document was autogenerated by xacro from robot.xacro                    | -->
<!-- |    EDITING THIS FILE BY HAND IS NOT RECOMMENDED                                 | -->
<!-- =================================================================================== -->
<robot name="b1_description">
  <material name="black">
    <color rgba="0.0 0.0 0.0 1.0"/>
  </material>
  <material name="blue">
    <color rgba="0.0 0.0 0.8 1.0"/>
  </material>
  <material name="green">
    <color rgba="0.0 0.8 0.0 1.0"/>
  </material>
  <material name="grey">
    <color rgba="0.2 0.2 0.2 1.0"/>
  </material>
  <material name="silver">
    <color rgba="0.9137254901960784 0.9137254901960784 0.8470588235294118 1.0"/>
  </material>
  <material name="orange">
    <color rgba="1.0 0.4235294117647059 0.0392156862745098 1.0"/>
  </material>
  <material name="brown">
    <color rgba="0.8705882352941177 0.8117647058823529 0.7647058823529411 1.0"/>
  </material>
  <material name="red">
    <color rgba="0.8 0.0 0.0 1.0"/>
  </material>
  <material name="white">
    <color rgba="1.0 1.0 1.0 1.0"/>
  </material>
  
  <link name="base">
    <visual>
      <origin rpy="0 0 0" xyz="0 0 0"/>
      <geometry>
        <box size="0.001 0.001 0.001"/>
      </geometry>
    </visual>
  </link>
  <joint name="floating_base" type="fixed">
    <origin rpy="0 0 0" xyz="0 0 0"/>
    <parent link="base"/>
    <child link="trunk"/>
  </joint>
  <link name="trunk">
    <visual>
      <origin rpy="0 0 0" xyz="0 0 0"/>
      <geometry>
        <mesh filename="meshes/trunk.dae" scale="1 1 1"/>
      </geometry>
      <material name="orange"/>
    </visual>
    <collision>
      <origin rpy="0 0 0" xyz="0 0 0"/>
      <geometry>
        <box size="0.647 0.3 0.15"/>
      </geometry>
    </collision>
    <!-- <collision>
            <origin rpy="0 0 0" xyz="0 0 0"/>
            <geometry>
                <mesh filename="meshes/trunk.dae" scale="1 1 1"/>
            </geometry>
        </collision> -->
    <inertial>
      <origin rpy="0 0 0" xyz="0.008987 0.002243 0.003013"/>
      <mass value="25"/>
      <inertia ixx="0.183142146" ixy="-0.001379002" ixz="-0.027956055" iyy="0.756327752" iyz="0.000193774" izz="0.783777558"/>
    </inertial>
  </link>
  <joint name="imu_joint" type="fixed">
    <parent link="trunk"/>
    <child link="imu_link"/>
    <origin rpy="0 0 0" xyz="0 0 0"/>
  </joint>
  <link name="imu_link">
    <inertial>
      <mass value="0.001"/>
      <origin rpy="0 0 0" xyz="0 0 0"/>
      <inertia ixx="0.0001" ixy="0" ixz="0" iyy="0.000001" iyz="0" izz="0.0001"/>
    </inertial>
    <visual>
      <origin rpy="0 0 0" xyz="0 0 0"/>
      <geometry>
        <box size="0.001 0.001 0.001"/>
      </geometry>
      <material name="red"/>
    </visual>
    <collision>
      <origin rpy="0 0 0" xyz="0 0 0"/>
      <geometry>
        <box size=".001 .001 .001"/>
      </geometry>
    </collision>
  </link>
  <joint name="FR_hip_joint" type="revolute">
    <origin rpy="0 0 0" xyz="0.3455 -0.072 0"/>
    <parent link="trunk"/>
    <child link="FR_hip"/>
    <axis xyz="1 0 0"/>
    <dynamics damping="0" friction="0"/>
    <limit effort="91.0035" lower="-0.75" upper="0.75" velocity="19.69"/>
  </joint>
  <link name="FR_hip">
    <visual>
      <origin rpy="3.141592653589793 0 0" xyz="0 0 0"/>
      <geometry>
        <mesh filename="meshes/hip.dae" scale="1 1 1"/>
      </geometry>
      <material name="orange"/>
    </visual>
    <collision>
      <origin rpy="1.5707963267948966 0 0" xyz="0 -0.12675 0"/>
      <geometry>
        <cylinder length="0.04" radius="0.09"/>
      </geometry>
    </collision>
    <inertial>
      <origin rpy="0 0 0" xyz="-0.020298 -0.009758 0.000109"/>
      <mass value="2.1"/>
      <inertia ixx="0.00406608" ixy="0.000288071" ixz="-4.371e-06" iyy="0.008775259" iyz="-1.811e-06" izz="0.006060348"/>
    </inertial>
  </link>
  <joint name="FR_thigh_joint" type="revolute">
    <origin rpy="0 0 0" xyz="0 -0.12675 0"/>
    <parent link="FR_hip"/>
    <child link="FR_thigh"/>
    <axis xyz="0 1 0"/>
    <dynamics damping="0" friction="0"/>
    <limit effort="93.33" lower="-1.0" upper="3.5" velocity="23.32"/>
  </joint>
  <link name="FR_thigh">
    <visual>
      <origin rpy="0 0 0" xyz="0 0 0"/>
      <geometry>
        <mesh filename="meshes/thigh_mirror.dae" scale="1 1 1"/>
      </geometry>
      <material name="orange"/>
    </visual>
    <collision>
      <origin rpy="0 1.5707963267948966 0" xyz="0 0 -0.175"/>
      <geometry>
        <box size="0.35 0.05 0.08"/>
      </geometry>
    </collision>
    <inertial>
      <origin rpy="0 0 0" xyz="-0.000235 0.028704 -0.054169"/>
      <mass value="3.934"/>
      <inertia ixx="0.044459086" ixy="-0.000128738" ixz="-0.002343913" iyy="0.046023457" iyz="-0.006032996" izz="0.008696078"/>
    </inertial>
  </link>
  <joint name="FR_calf_joint" type="revolute">
    <origin rpy="0 0 0" xyz="0 0 -0.35"/>
    <parent link="FR_thigh"/>
    <child link="FR_calf"/>
    <axis xyz="0 1 0"/>
    <dynamics damping="0" friction="0"/>
    <limit effort="140" lower="-2.6" upper="-0.6" velocity="15.55"/>
  </joint>
  <link name="FR_calf">
    <visual>
      <origin rpy="0 0 0" xyz="0 0 0"/>
      <geometry>
        <mesh filename="meshes/calf.dae" scale="1 1 1"/>
      </geometry>
      <material name="orange"/>
    </visual>
    <collision>
      <origin rpy="0 1.5707963267948966 0" xyz="0 0 -0.175"/>
      <geometry>
        <box size="0.35 0.04 0.05"/>
      </geometry>
    </collision>
    <inertial>
      <origin rpy="0 0 0" xyz="0.005237 0.0 -0.202805"/>
      <mass value="0.857"/>
      <inertia ixx="0.015011003" ixy="5.2e-08" ixz="0.000250042" iyy="0.015159462" iyz="4.61e-07" izz="0.000375749"/>
    </inertial>
  </link>
  <joint name="FR_foot_fixed" type="fixed" dont_collapse="true">
    <origin rpy="0 0 0" xyz="0 0 -0.35"/>
    <parent link="FR_calf"/>
    <child link="FR_foot"/>
  </joint>
  <link name="FR_foot">
    <visual>
      <origin rpy="0 0 0" xyz="0 0 0"/>
      <geometry>
        <sphere radius="0.03"/>
      </geometry>
      <material name="green"/>
    </visual>
    <collision>
      <origin rpy="0 0 0" xyz="0 0 0"/>
      <geometry>
        <sphere radius="0.04"/>
      </geometry>
    </collision>
    <inertial>
      <mass value="0.05"/>
      <inertia ixx="3.2e-05" ixy="0.0" ixz="0.0" iyy="3.2e-05" iyz="0.0" izz="3.2e-05"/>
    </inertial>
  </link>
  
  <joint name="FL_hip_joint" type="revolute">
    <origin rpy="0 0 0" xyz="0.3455 0.072 0"/>
    <parent link="trunk"/>
    <child link="FL_hip"/>
    <axis xyz="1 0 0"/>
    <dynamics damping="0" friction="0"/>
    <limit effort="91.0035" lower="-0.75" upper="0.75" velocity="19.69"/>
  </joint>
  <link name="FL_hip">
    <visual>
      <origin rpy="0 0 0" xyz="0 0 0"/>
      <geometry>
        <mesh filename="meshes/hip.dae" scale="1 1 1"/>
      </geometry>
      <material name="orange"/>
    </visual>
    <collision>
      <origin rpy="1.5707963267948966 0 0" xyz="0 0.12675 0"/>
      <geometry>
        <cylinder length="0.04" radius="0.09"/>
      </geometry>
    </collision>
    <inertial>
      <origin rpy="0 0 0" xyz="-0.020298 0.009758 0.000109"/>
      <mass value="2.1"/>
      <inertia ixx="0.00406608" ixy="-0.000288071" ixz="-4.371e-06" iyy="0.008775259" iyz="1.811e-06" izz="0.006060348"/>
    </inertial>
  </link>
  <joint name="FL_thigh_joint" type="revolute">
    <origin rpy="0 0 0" xyz="0 0.12675 0"/>
    <parent link="FL_hip"/>
    <child link="FL_thigh"/>
    <axis xyz="0 1 0"/>
    <dynamics damping="0" friction="0"/>
    <limit effort="93.33" lower="-1.0" upper="3.5" velocity="23.32"/>
  </joint>
  <link name="FL_thigh">
    <visual>
      <origin rpy="0 0 0" xyz="0 0 0"/>
      <geometry>
        <mesh filename="meshes/thigh.dae" scale="1 1 1"/>
      </geometry>
      <material name="orange"/>
    </visual>
    <collision>
      <origin rpy="0 1.5707963267948966 0" xyz="0 0 -0.175"/>
      <geometry>
        <box size="0.35 0.05 0.08"/>
      </geometry>
    </collision>
    <inertial>
      <origin rpy="0 0 0" xyz="-0.000235 -0.028704 -0.054169"/>
      <mass value="3.934"/>
      <inertia ixx="0.044459086" ixy="0.000128738" ixz="-0.002343913" iyy="0.046023457" iyz="0.006032996" izz="0.008696078"/>
    </inertial>
  </link>
  <joint name="FL_calf_joint" type="revolute">
    <origin rpy="0 0 0" xyz="0 0 -0.35"/>
    <parent link="FL_thigh"/>
    <child link="FL_calf"/>
    <axis xyz="0 1 0"/>
    <dynamics damping="0" friction="0"/>
    <limit effort="140" lower="-2.6" upper="-0.6" velocity="15.55"/>
  </joint>
  <link name="FL_calf">
    <visual>
      <origin rpy="0 0 0" xyz="0 0 0"/>
      <geometry>
        <mesh filename="meshes/calf.dae" scale="1 1 1"/>
      </geometry>
      <material name="orange"/>
    </visual>
    <collision>
      <origin rpy="0 1.5707963267948966 0" xyz="0 0 -0.175"/>
      <geometry>
        <box size="0.35 0.04 0.05"/>
      </geometry>
    </collision>
    <inertial>
      <origin rpy="0 0 0" xyz="0.005237 0.0 -0.202805"/>
      <mass value="0.857"/>
      <inertia ixx="0.015011003" ixy="5.2e-08" ixz="0.000250042" iyy="0.015159462" iyz="4.61e-07" izz="0.000375749"/>
    </inertial>
  </link>
  <joint name="FL_foot_fixed" type="fixed" dont_collapse="true">
    <origin rpy="0 0 0" xyz="0 0 -0.35"/>
    <parent link="FL_calf"/>
    <child link="FL_foot"/>
  </joint>
  <link name="FL_foot">
    <visual>
      <origin rpy="0 0 0" xyz="0 0 0"/>
      <geometry>
        <sphere radius="0.03"/>
      </geometry>
      <material name="green"/>
    </visual>
    <collision>
      <origin rpy="0 0 0" xyz="0 0 0"/>
      <geometry>
        <sphere radius="0.04"/>
      </geometry>
    </collision>
    <inertial>
      <mass value="0.05"/>
      <inertia ixx="3.2e-05" ixy="0.0" ixz="0.0" iyy="3.2e-05" iyz="0.0" izz="3.2e-05"/>
    </inertial>
  </link>
  <joint name="RR_hip_joint" type="revolute">
    <origin rpy="0 0 0" xyz="-0.3455 -0.072 0"/>
    <parent link="trunk"/>
    <child link="RR_hip"/>
    <axis xyz="1 0 0"/>
    <dynamics damping="0" friction="0"/>
    <limit effort="91.0035" lower="-0.75" upper="0.75" velocity="19.69"/>
  </joint>
  <link name="RR_hip">
    <visual>
      <origin rpy="3.141592653589793 3.141592653589793 0" xyz="0 0 0"/>
      <geometry>
        <mesh filename="meshes/hip.dae" scale="1 1 1"/>
      </geometry>
      <material name="orange"/>
    </visual>
    <collision>
      <origin rpy="1.5707963267948966 0 0" xyz="0 -0.12675 0"/>
      <geometry>
        <cylinder length="0.04" radius="0.09"/>
      </geometry>
    </collision>
    <inertial>
      <origin rpy="0 0 0" xyz="0.020298 -0.009758 0.000109"/>
      <mass value="2.1"/>
      <inertia ixx="0.00406608" ixy="-0.000288071" ixz="4.371e-06" iyy="0.008775259" iyz="-1.811e-06" izz="0.006060348"/>
    </inertial>
  </link>
  <joint name="RR_thigh_joint" type="revolute">
    <origin rpy="0 0 0" xyz="0 -0.12675 0"/>
    <parent link="RR_hip"/>
    <child link="RR_thigh"/>
    <axis xyz="0 1 0"/>
    <dynamics damping="0" friction="0"/>
    <limit effort="93.33" lower="-1.0" upper="3.5" velocity="23.32"/>
  </joint>
  <link name="RR_thigh">
    <visual>
      <origin rpy="0 0 0" xyz="0 0 0"/>
      <geometry>
        <mesh filename="meshes/thigh_mirror.dae" scale="1 1 1"/>
      </geometry>
      <material name="orange"/>
    </visual>
    <collision>
      <origin rpy="0 1.5707963267948966 0" xyz="0 0 -0.175"/>
      <geometry>
        <box size="0.35 0.05 0.08"/>
      </geometry>
    </collision>
    <inertial>
      <origin rpy="0 0 0" xyz="-0.000235 0.028704 -0.054169"/>
      <mass value="3.934"/>
      <inertia ixx="0.044459086" ixy="-0.000128738" ixz="-0.002343913" iyy="0.046023457" iyz="-0.006032996" izz="0.008696078"/>
    </inertial>
  </link>
  <joint name="RR_calf_joint" type="revolute">
    <origin rpy="0 0 0" xyz="0 0 -0.35"/>
    <parent link="RR_thigh"/>
    <child link="RR_calf"/>
    <axis xyz="0 1 0"/>
    <dynamics damping="0" friction="0"/>
    <limit effort="140" lower="-2.6" upper="-0.6" velocity="15.55"/>
  </joint>
  <link name="RR_calf">
    <visual>
      <origin rpy="0 0 0" xyz="0 0 0"/>
      <geometry>
        <mesh filename="meshes/calf.dae" scale="1 1 1"/>
      </geometry>
      <material name="orange"/>
    </visual>
    <collision>
      <origin rpy="0 1.5707963267948966 0" xyz="0 0 -0.175"/>
      <geometry>
        <box size="0.35 0.04 0.05"/>
      </geometry>
    </collision>
    <inertial>
      <origin rpy="0 0 0" xyz="0.005237 0.0 -0.202805"/>
      <mass value="0.857"/>
      <inertia ixx="0.015011003" ixy="5.2e-08" ixz="0.000250042" iyy="0.015159462" iyz="4.61e-07" izz="0.000375749"/>
    </inertial>
  </link>
  <joint name="RR_foot_fixed" type="fixed" dont_collapse="true">
    <origin rpy="0 0 0" xyz="0 0 -0.35"/>
    <parent link="RR_calf"/>
    <child link="RR_foot"/>
  </joint>
  <link name="RR_foot">
    <visual>
      <origin rpy="0 0 0" xyz="0 0 0"/>
      <geometry>
        <sphere radius="0.03"/>
      </geometry>
      <material name="green"/>
    </visual>
    <collision>
      <origin rpy="0 0 0" xyz="0 0 0"/>
      <geometry>
        <sphere radius="0.04"/>
      </geometry>
    </collision>
    <inertial>
      <mass value="0.05"/>
      <inertia ixx="3.2e-05" ixy="0.0" ixz="0.0" iyy="3.2e-05" iyz="0.0" izz="3.2e-05"/>
    </inertial>
  </link>

  <joint name="RL_hip_joint" type="revolute">
    <origin rpy="0 0 0" xyz="-0.3455 0.072 0"/>
    <parent link="trunk"/>
    <child link="RL_hip"/>
    <axis xyz="1 0 0"/>
    <dynamics damping="0" friction="0"/>
    <limit effort="91.0035" lower="-0.75" upper="0.75" velocity="19.69"/>
  </joint>
  <link name="RL_hip">
    <visual>
      <origin rpy="0 3.141592653589793 0" xyz="0 0 0"/>
      <geometry>
        <mesh filename="meshes/hip.dae" scale="1 1 1"/>
      </geometry>
      <material name="orange"/>
    </visual>
    <collision>
      <origin rpy="1.5707963267948966 0 0" xyz="0 0.12675 0"/>
      <geometry>
        <cylinder length="0.04" radius="0.09"/>
      </geometry>
    </collision>
    <inertial>
      <origin rpy="0 0 0" xyz="0.020298 0.009758 0.000109"/>
      <mass value="2.1"/>
      <inertia ixx="0.00406608" ixy="0.000288071" ixz="4.371e-06" iyy="0.008775259" iyz="1.811e-06" izz="0.006060348"/>
    </inertial>
  </link>
  <joint name="RL_thigh_joint" type="revolute">
    <origin rpy="0 0 0" xyz="0 0.12675 0"/>
    <parent link="RL_hip"/>
    <child link="RL_thigh"/>
    <axis xyz="0 1 0"/>
    <dynamics damping="0" friction="0"/>
    <limit effort="93.33" lower="-1.0" upper="3.5" velocity="23.32"/>
  </joint>
  <link name="RL_thigh">
    <visual>
      <origin rpy="0 0 0" xyz="0 0 0"/>
      <geometry>
        <mesh filename="meshes/thigh.dae" scale="1 1 1"/>
      </geometry>
      <material name="orange"/>
    </visual>
    <collision>
      <origin rpy="0 1.5707963267948966 0" xyz="0 0 -0.175"/>
      <geometry>
        <box size="0.35 0.05 0.08"/>
      </geometry>
    </collision>
    <inertial>
      <origin rpy="0 0 0" xyz="-0.000235 -0.028704 -0.054169"/>
      <mass value="3.934"/>
      <inertia ixx="0.044459086" ixy="0.000128738" ixz="-0.002343913" iyy="0.046023457" iyz="0.006032996" izz="0.008696078"/>
    </inertial>
  </link>
  <joint name="RL_calf_joint" type="revolute">
    <origin rpy="0 0 0" xyz="0 0 -0.35"/>
    <parent link="RL_thigh"/>
    <child link="RL_calf"/>
    <axis xyz="0 1 0"/>
    <dynamics damping="0" friction="0"/>
    <limit effort="140" lower="-2.6" upper="-0.6" velocity="15.55"/>
  </joint>
  <link name="RL_calf">
    <visual>
      <origin rpy="0 0 0" xyz="0 0 0"/>
      <geometry>
        <mesh filename="meshes/calf.dae" scale="1 1 1"/>
      </geometry>
      <material name="orange"/>
    </visual>
    <collision>
      <origin rpy="0 1.5707963267948966 0" xyz="0 0 -0.175"/>
      <geometry>
        <box size="0.35 0.04 0.05"/>
      </geometry>
    </collision>
    <inertial>
      <origin rpy="0 0 0" xyz="0.005237 0.0 -0.202805"/>
      <mass value="0.857"/>
      <inertia ixx="0.015011003" ixy="5.2e-08" ixz="0.000250042" iyy="0.015159462" iyz="4.61e-07" izz="0.000375749"/>
    </inertial>
  </link>
  <joint name="RL_foot_fixed" type="fixed" dont_collapse="true">
    <origin rpy="0 0 0" xyz="0 0 -0.35"/>
    <parent link="RL_calf"/>
    <child link="RL_foot"/>
  </joint>
  <link name="RL_foot">
    <visual>
      <origin rpy="0 0 0" xyz="0 0 0"/>
      <geometry>
        <sphere radius="0.03"/>
      </geometry>
      <material name="green"/>
    </visual>
    <collision>
      <origin rpy="0 0 0" xyz="0 0 0"/>
      <geometry>
        <sphere radius="0.04"/>
      </geometry>
    </collision>
    <inertial>
      <mass value="0.05"/>
      <inertia ixx="3.2e-05" ixy="0.0" ixz="0.0" iyy="3.2e-05" iyz="0.0" izz="3.2e-05"/>
    </inertial>
  </link>
</robot>

